Workbook
Name ___xlnm._FilterDatabase_1: #REF!
Name ___xlnm._FilterDatabase_1: #REF!
Name ___xlnm._FilterDatabase_1: #REF!
Name ___xlnm._FilterDatabase_1: #REF!
Name ___xlnm._FilterDatabase_1: #REF!
Name ___xlnm._FilterDatabase_1: #REF!
Name __xlnm._FilterDatabase_1: #REF!
Name __xlnm._FilterDatabase_1: #REF!
Name __xlnm._FilterDatabase_1: #REF!
Name __xlnm._FilterDatabase_1: #REF!
Name __xlnm._FilterDatabase_1: #REF!
Name __xlnm._FilterDatabase_1: #REF!
Name Capex: #REF!

Sheet ИНФ
B1: Заполнить
B2: Договор № | C2: ТО-ЭСТ-РО-2025 | D2: 46111
B3: Договор от | C3: 45901
B4: Период | C4: ОРЕХ 2612-2613
B5: Доп название
B6: Начало | C6: 16.03.2026г
B7: Конец | C7: 29.03.2026г.
B8: Автозаполнение | C8: ООО "ЮСТК-Энергострой", 350000, г. Краснодар, ул. Сливовая, 33
B9: Автозаполнение | C9: Азаренко Р. Г.
A10: ИСПОЛНИТЕЛЬ | B10: Организация исполнителя | C10: ООО "ЭСТ", 350005, Краснодарский край, г. Краснодар, ул. им. Александра Покрышкина д. 25/А, корп.2, помещ. 21,22,23
B11: Представитель исполнителя | C11: Нестеренко Е.В.
B12: Должность исполнителя | C12: Директор ООО "ЭСТ"
B13: ОКПО Исполнителя | C13: 91130665
A14: ЗАКАЗЧИК | B14: Представитель заказчика | C14: Мотлях К.Г.
B15: Должность заказчика | C15: Директор макрорегионального филиала "Юг" ОOO "Т2 Мобайл"
B16: Организация заказчика | C16: ООО "Т2 Мобайл", 108811, г. Москва, Киевское шоссе 22-й километр, домовладение 6, строение 1, этаж 5, комната 33
B17: ОКПО Заказчика | C17: 17872715

Sheet Работы
A1: № п/п | B1: Наименование работ* | C1: Ед. Изм. | D1: Цена за единицу в рублях без НДС
A2: 1. Антенно - фидерное устройство Объекта
A3: .1.1. | B3: Диагностика, измерение потерь оптической линии между аппаратной и оборудованием на АМС рефлектометром (длина линии, расстояние до повреждения, затухание) | C3: шт. | D3: 503
A4: 1.2. | B4: Диагностика и устранение дефектов АФУ сектора БС (локализация неисправности или перепуток Net Monitor'ом, проверка/ремонт разъёмов, соединительных джемперов, проверка КСВ) | C4: Объект | D4: 4180
A5: 1.3. | B5: Замена RF кабеля БС 1/2, RF кабеля РРЛ (с установкой креплений, заземлением, включая крепёжные элементы) | C5: м.п. | D5: 205
A6: 1.4. | B6: Замена RF кабеля БС 7/8 (с установкой креплений, заземлением, включая крепёжные элементы) | C6: м.п. | D6: 270
A7: 1.5. | B7: Замена RF кабеля GPS антенны | C7: м.п. | D7: 158
A8: 1.6. | B8: Диагностика, замена или ремонт RF разъёмов БС и RF разъёмов РРЛ N-type на АМС | C8: шт. | D8: 2365
A9: 1.7. | B9: Диагностика, замена или ремонт RF разъёмов БС и RF разъёмов РРЛ N-type в аппаратной | C9: шт. | D9: 773
A10: 1.8. | B10: Диагностика и замена outdoor джамперов 1/2" | C10: шт. | D10: 2728
A11: 1.9. | B11: Диагностика и замена indoor джамперов 1/2" | C11: шт. | D11: 1489
A12: 1.10. | B12: Диагностика и замена кабеля управления RET | C12: шт. | D12: 2104
A13: 1.11. | B13: Диагностика и замена устройств регулировки угла наклона (RET) | C13: шт. | D13: 2160
A14: 1.12. | B14: Замена, подключение и юстировка антенн базовых станций (вкл. джамперы, заземления, грозоразрядники) | C14: шт. | D14: 6935
... A25: 1.23. | B25: Измерение мощности оптического сигнала | C25: волокно | D25: 140
A26: 2. Оборудование Объекта
A27: 2.1. | B27: Диагностика и замена модуля передатчиков БС в аппаратной, включая монтаж всех крепёжных элементов и кабелей, переключение джемперов и созданием логических объектов на стороне БС | C27: шт. | D27: 1052
A28: 2.2. | B28: Диагностика и замена модуля передатчиков БС на АМС, включая монтаж всех крепёжных элементов и кабелей, переключение джамперов и созданием логических объектов на стороне БС | C28: шт. | D28: 2830
A29: 2.3. | B29: Диагностика и замена системного модуля БС в аппаратной или ниже 10м на Объекте (включая монтаж всех крепёжных элементов и кабелей и создание логических объектов на стороне БС) | C29: шт. | D29: 1117
A30: 2.4. | B30: Диагностика и замена системного модуля БС на АМС (включая монтаж всех крепёжных элементов и кабелей, переключение джамперов и созданием логических объектов на стороне БС) | C30: шт. | D30: 2830
A31: 2.5. | B31: Диагностика и замена модуля в корзине БС (TCU, FIQB, FTIF, FIQA, или аналогичного) или платы расширения системы (FBBA и аналогичного) в аппаратной или ниже 10 метров на Объекте, включая монтаж всех крепёжных элементов и кабелей. Создание логических объектов на стороне БС | C31: шт. | D31: 624
A32: 2.6. | B32: Диагностика и замена модуля в корзине БС (TCU, FIQB, FTIF, FIQA, или аналогичного) или платы расширения системы (FBBA и аналогичного) на АМС, выше 10 метров, включая монтаж всех крепёжных элементов и кабелей. Создание логических объектов на стороне БС | C32: шт. | D32: 1359
A33: 2.7. | B33: Диагностика и замена корзины питания модулей DUW/DUS/TCU или аналогичных | C33: шт. | D33: 1117
A34: 2.8. | B34: Диагностика и замена оптического модуля SFP в оборудование, смонтированное в аппаратной или ниже 10 метров | C34: шт. | D34: 130
A35: 2.9. | B35: Диагностика и замена оптического модуля SFP в оборудование, смонтированное на АМС, выше 10 метров | C35: шт. | D35: 987
A36: 2.10. | B36: Замена и подключение кабелей питания DC 48В между системой питания и оборудованием БС или трансмиссии в аппаратной | C36: м.п. | D36: 400
A37: 2.11. | B37: Диагностика, замена FAN-модуля (вентиляторов в EXDA, FXEA, FXEB или аналогичных модулях) | C37: шт. | D37: 307
A38: 2.12. | B38: Диагностика, замена соединительных кабелей на АМС (Power, заземление) | C38: м.п. | D38: 484
... A53: 2.27. | B53: Чистка от загрязнения вентиляторов выпрямителей, внутренних модулей БС, трансмиссии | C53: модуль | D53: 493
A54: 3. Работы в отношении антенно - фидерного устройства радиорелейной линии (РРЛ)
A55: 3.1. | B55: Замена антенны РРЛ 0,3 м (в комплекте с радиомодулем), заземление | C55: шт. | D55: 3807
A56: 3.2. | B56: Замена антенны РРЛ 0,6 (0,9) м (в комплекте с радиомодулем), заземление | C56: шт. | D56: 5520
A57: 3.3. | B57: Замена антенны РРЛ 1,2 – 1,8 м (в комплекте с радиомодулем), заземление | C57: шт. | D57: 7727
A58: 3.4. | B58: Юстировка РРЛ пролёта (диам. от 0,3 до 0,9м) | C58: пролёт | D58: 3686
A59: 3.5. | B59: Юстировка РРЛ пролёта (диам. от 1м до 1,8) | C59: пролёт | D59: 5148
A60: 3.6. | B60: Юстировка РРЛ полупролета (диам. от 0,3 до 0,9м) | C60: полупролёт | D60: 1843
A61: 3.7. | B61: Юстировка РРЛ полупролета (диам. от 1м до 1,8) | C61: полупролёт | D61: 2579
A62: 3.8. | B62: Диагностика, замена, ремонт заземления РРЛ-фидера (Комплект на один фидер) | C62: комплект | D62: 484
A63: 3.9. | B63: Восстановление крепления кабелей РРЛ, оптических кабелей, цифровых кабелей (1xAlarm, 1xLMP, 4xE1, 2xEthernet), кабелей питания DC (СИП 4*35, 4*50, ВБбШв2*25) по кабельному мосту, АМС включая зажимы, стяжки | C63: м.п. | D63: 158
A64: 3.10. | B64: Герметизация соединения оптического кабеля (между системным блоком и радиоблоком) включая материал лента VM, лента 88Т | C64: шт. | D64: 214
...

Sheet Расстояния
A1: № пп | B1: № Объекта (БС) | C1: Тип Объекта * | D1: Адрес БС (ДС от 15.08.2023) | E1: Срок реагирования, в часах | F1: Объект находится в труднодоступной местности (ДА / НЕТ) | G1: Требуется авиа-/жд транспорт или иное (ДА / НЕТ, УКАЗАТЬ ВИД) | H1: Возможность компенсации длительного пребывания (ДА / НЕТ) | I1: Место нахождения комплекта ключей | J1: Расстояние до Объекта, км | K1: Осн./Доп. | L1: GPS-широта | M1: GPS-долгота
A2: 1 | B2: RO0305 | C2: 22:собст. АМС выше 10 м на крыше | D2: Егорлыкский район, станица Егорлыкская, улица Чапаева, 144 | E2: 2.62 | F2: нет | G2: нет | H2: нет | I2: Сальск | J2: 81 | K2: осн. | L2: 46.58075 | M2: 40.654667
A3: =A2+1 -> 2 | B3: RO0306 | C3: 21:собст. АМС до 10 м на крыше | D3: Целинский район, поселок Целина, 1-я линия, №1 | E3: 1.94 | F3: нет | G3: нет | H3: нет | I3: Сальск | J3: 47 | K3: осн. | L3: 46.53825 | M3: 41.061333
A4: =A3+1 -> 3 | B4: RO0307 | C4: 21:собст. АМС до 10 м на крыше | D4: Сальский район, г. Сальск, улица Промышленная, 1 | E4: 1.22 | F4: нет | G4: нет | H4: нет | I4: Сальск | J4: 11 | K4: осн. | L4: 46.473639 | M4: 41.564833
A5: =A4+1 -> 4 | B5: RO0308 | C5: 32:трубостойки/АМС на: трубе, элеваторе, водонап.башне | D5: Район Сальский, Город Сальск, Улица Николая Островского 6-е | E5: 1.28 | F5: нет | G5: нет | H5: нет | I5: Сальск | J5: 14 | K5: осн. | L5: 46.456389 | M5: 41.538889
A6: =A5+1 -> 5 | B6: RO0309 | C6: 31:трубостойки на чужой АМС на земле/крыше | D6: Сальский район, поселок Конезавод им. Буденного, улица Сальская, 53 | E6: 1 | F6: нет | G6: нет | H6: нет | I6: Сальск | J6: 0 | K6: осн. | L6: 46.538361 | M6: 41.577833
A7: =A6+1 -> 6 | B7: RO0310 | C7: 21:собст. АМС до 10 м на крыше | D7: Пролетарский район, г. Пролетарск, улица Чкалова, 12 | E7: 1.48 | F7: нет | G7: нет | H7: нет | I7: Сальск | J7: 24 | K7: осн. | L7: 46.71075 | M7: 41.70775
A8: =A7+1 -> 7 | B8: RO0311 | C8: 31:трубостойки на чужой АМС на земле/крыше | D8: Сальский район, поселок Гигант, улица Автодорожная, 66 | E8: 1.46 | F8: нет | G8: нет | H8: нет | I8: Сальск | J8: 23 | K8: осн. | L8: 46.515833 | M8: 41.356972
A9: =A8+1 -> 8 | B9: RO0312 | C9: 31:трубостойки на чужой АМС на земле/крыше | D9: Сальский район, село Новый Егорлык, улица Советская, 17А | E9: 1.78 | F9: нет | G9: нет | H9: нет | I9: Сальск | J9: 39 | K9: осн. | L9: 46.407667 | M9: 41.853639
A10: =A9+1 -> 9 | B10: RO0313 | C10: 31:трубостойки на чужой АМС на земле/крыше | D10: Орловский район, поселок Орловский, улица Ленина, 252 | E10: 2.24 | F10: нет | G10: нет | H10: нет | I10: Сальск | J10: 62 | K10: осн. | L10: 46.867667 | M10: 42.080472
A11: =A10+1 -> 10 | B11: RO0317 | C11: 13:собст. железобетонный столб с заглубленным фундаментом | D11: Сальский район, г. Сальск, улица Павлова, 2 | E11: 1.22 | F11: нет | G11: нет | H11: нет | I11: Сальск | J11: 11 | K11: осн. | L11: 46.475361 | M11: 41.532639
A12: =A11+1 -> 11 | B12: RO0318 | C12: 13:собст. железобетонный столб с заглубленным фундаментом | D12: Сальский район, г. Сальск, улица Юннатов, 3/2 | E12: 1.18 | F12: нет | G12: нет | H12: нет | I12: Сальск | J12: 9 | K12: осн. | L12: 46.485833 | M12: 41.550556
A13: =A12+1 -> 12 | B13: RO0319 | C13: 13:собст. железобетонный столб с заглубленным фундаментом | D13: Пролетарский район, г. Пролетарск, улица 50 лет Октября, 24 | E13: 1.5 | F13: нет | G13: нет | H13: нет | I13: Сальск | J13: 25 | K13: осн. | L13: 46.698056 | M13: 41.727778
A14: =A13+1 -> 13 | B14: RO0321 | C14: 13:собст. железобетонный столб с заглубленным фундаментом | D14: Сальский район, г. Сальск, улица Свободы, 302А/2 | E14: 1.3 | F14: нет | G14: нет | H14: нет | I14: Сальск | J14: 15 | K14: осн. | L14: 46.470556 | M14: 41.511944
... A1700: =A1699+1 -> 1699 | B1700: RO2832 | C1700: 30:трубостойки на АМС БК Пилар | D1700: Область Ростовская, Район Заветинский, Хутор Шебалин\примерно 15 м по направлению на север от границ земельного участка по адресу: ул. Гагарина, 7, кв.2 | E1700: 3.96 | F1700: нет | G1700: нет | H1700: нет | I1700: Волгодонск | J1700: 148 | K1700: доп. | L1700: 47.36459 | M1700: 43.61736
B1701: RO2370 | F1701: нет | G1701: нет | H1701: нет | J1701: 70 | K1701: осн.
B1702: RO2541 | F1702: нет | G1702: нет | H1702: нет | J1702: 25 | K1702: осн.
B1703: RO1219 | F1703: нет | G1703: нет | H1703: нет | J1703: 15 | K1703: осн.
B1704: RO0466 | F1704: нет | G1704: нет | H1704: нет | J1704: 50 | K1704: осн.
B1705: RO1169 | F1705: нет | G1705: нет | H1705: нет | J1705: 40 | K1705: осн.
B1706: RO2446 | F1706: нет | G1706: нет | H1706: нет | J1706: 5 | K1706: осн.
B1707: RO2976 | F1707: нет | G1707: нет | H1707: нет | J1707: 15 | K1707: осн.
B1708: RO1478 | F1708: нет | G1708: нет | H1708: нет | J1708: 58 | K1708: осн.
B1709: RO0869 | F1709: нет | G1709: нет | H1709: нет | I1709: Сальская | J1709: 88 | K1709: осн.
B1710: RO1384 | F1710: нет | G1710: нет | H1710: нет | I1710: Таганрогская | J1710: 33 | K1710: осн.
B1711: RO1478 | F1711: нет | G1711: нет | H1711: нет | I1711: Таганрогская | J1711: 54 | K1711: осн.
B1712: RO2277 | F1712: нет | G1712: нет | H1712: нет | I1712: Сальская | J1712: 30 | K1712: осн.
B1713: RO2339 | F1713: нет | G1713: нет | H1713: нет | I1713: Таганрогская | J1713: 10 | K1713: осн.
B1714: RO2717 | F1714: нет | G1714: нет | H1714: нет | I1714: Таганрогская | J1714: 62 | K1714: осн.
B1715: RO0950 | F1715: нет | G1715: нет | H1715: нет | I1715: Таганрогская | J1715: 48 | K1715: осн.
B1716: RO1064 | F1716: нет | G1716: нет | H1716: нет | I1716: Таганрогская NEW | J1716: 72 | K1716: осн.
B1717: RO1181 | F1717: нет | G1717: нет | H1717: нет | I1717: Таганрогская | J1717: 55 | K1717: осн.
B1718: RO1253 | F1718: нет | G1718: нет | H1718: нет | I1718: Сальская | J1718: 14 | K1718: осн.
B1719: RO1312 | F1719: нет | G1719: нет | H1719: нет | I1719: Таганрогская | J1719: 14 | K1719: осн.
B1720: RO2044 | F1720: нет | G1720: нет | H1720: нет | I1720: Таганрогская | J1720: 38 | K1720: осн.
... B1724: RO2969 | F1724: нет | G1724: нет | H1724: нет | I1724: Таганрогская | J1724: 6 | K1724: осн.
B1725: RO1983 | F1725: нет | G1725: нет | H1725: нет | J1725: 16 | K1725: осн.
B1726: RO1196 | F1726: нет | G1726: нет | H1726: нет | J1726: 64 | K1726: осн.
B1727: RO0498 | F1727: нет | G1727: нет | H1727: нет | J1727: 66 | K1727: осн.
B1728: RO1984 | F1728: нет | G1728: нет | H1728: нет | J1728: 69 | K1728: осн.
...

Sheet Opex
M1: ПРИЛОЖЕНИЕ № 8 (Общий отчет)
M2: к Договору на выполнение работ
N3: № ТО-ЭСТ-РО-2025 от «01» сентября 2025 г.
A5: Отчет о выполнении Аварийно-восстановительных и Оперативных работ и работ по Техническому обслуживанию по типу расходов ОрЕх | P5: за период | T5: =CONCATENATE(ИНФ!C4, " ", ИНФ!C6, "-", ИНФ!C7) -> ОРЕХ 2612-2613 16.03.2026г-29.03.2026г.
B7: г. Ростов-на-Дону | N7: =ИНФ!D2 -> 46111
A8: Общество с ограниченной ответственностью «Т2-Мобайл» (Ростовский филиал) (сокращенное наименование ООО «Т2 Мобайл» Ростовский филиал), юридическое лицо, зарегистрированное по адресу: Российская Федерация, 108811, г. Москва, поселение Московский, Киевское шоссе 22-й километр, домовладение 6, строение 1, этаж 5, комната 33, в лице Руководителя Макрорегионального филиала "Юг" Общества с ограниченной ответственностью «Т2 Мобайл» Мотлях Константина Геннадьевича, действующего на основании доверенности №77/447-н/77-2024-3-169 от 15.02.2024 г. , именуемое в дальнейшем «Заказчик», с одной стороны, и Общество с ограниченной ответственностью «Эффективные сервисные технологии», юридическое лицо, зарегистрированное по адресу: Российская Федерация, 3350005, Краснодарский край, г. Краснодар, ул. им. Александра Покрышкина д. 25/А, корп.2, помещ. 21,22,23, в лице Директора Нестеренко Евгения Викторовича, действующего на основании Устава, именуемое в дальнейшем «Подрядчик», с другой стороны, совместно именуемые «Стороны», а по отдельности - «Сторона», составили Отчет о выполнении Аварийно – восстановительных и Оперативных работ и работ по Техническому обслуживанию к Акту выполненных работ № _____ от «__» ________ 20_ г. к Договору на выполнение работ № ТО-ЭСТ-РО-2025 от «01» сентября 2025 г. о нижеследующем:
O9: Оперативные работы, ТО, Инвентаризация | Q9: АВР по обеспечению временного энергоснабжения | U9: АВР
A10: № п/п | B10: № Объекта | C10: Расстояние до объекта | D10: Объект (основной/дополнительный) | E10: Объект, находящийся в труднодоступной местности | F10: Номер заявки | G10: Дата, Время заявки | H10: Дата и Время появления Подрядчика на Объекте | I10: Дата и Время ухода Подрядчика с Объекта | J10: ФИО сотрудника Исполнителя | K10: ФИО сотрудника Заказчика | L10: № п/п работ (по приложению №10) | M10: Наименование работ (по приложению №10) | N10: Описание фактически выполненных работ | O10: Оперативные работы, ТО, Инвентаризация. Количество | P10: Оперативные работы, ТО, Инвентаризация. Цена за единицу в рублях без НДС) | Q10: Генерация, ч | R10: Генерация более 24ч, сутки | S10: Генерация более 72ч, сутки | T10: Генерация, цена за единицу (в руб без НДС) | U10: АВР менее 5 часов в рабочее время, стоимость (в руб. без НДС) | V10: АВР менее 5 часов во внерабочее время, стоимость (в руб. без НДС) | W10: АВР свыше 5 часов в рабочее время (Ставка применяется по истечению 5 часа выполнения АВР), час | X10: АВР свыше 5 часов в нерабочее время (Ставка применяется по истечению 5 часа выполнения АВР), час | Y10: АВР свыше 5 часов (Ставка применяется по истечению 5 часа выполнения АВР) Цена за час (в руб. без НДС) | Z10: Отмена задания АВР, стоимость (в руб. без НДС) | AA10: Стоимость работ в заявке (в руб. без НДС) | AB10: Наименование Оборудования (Материалов), купленного по согласованию с Заказчиком | AC10: Кол-во Оборудования (Материалов), купленного по согласованию с Заказчиком | AD10: Стоимость Оборудования (Материалов), купленного по согласованию с Заказчиком руб. за штуку, без НДС | AE10: Общая стоимость Оборудования (Материалов), купленного по согласованию с Заказчиком,руб. без НДС | AF10: Стоимость километража, руб. | AG10: Стоимость Заявки с учетом километража, материалов и локации объекта, руб. без НДС | AH10: Тип штрафа согласно договору (пункт договора) | AI10: Размер штрафных санкций в процентах от стоимости работ | AJ10: Итоговая Стоимость Заявки с учетом штрафных санкций (руб. без НДС) | AK10: Счет ТПС (SAP) | AL10: Оплата за трудный доступ | AM10: Доплата по дополнительному объекту
A11: =ROW(A11)-10 -> 1 | B11: RO2821 | C11: 92 | D11: =VLOOKUP(B11, Расстояния!B:K, 10, 0) -> доп. | E11: =VLOOKUP(B11, Расстояния!B:F, 5, 0) -> нет | F11: WO06719799 | G11: 46104.678 | H11: 46104.698 | I11: 46104.747 | J11: Голиков | L11: 3.1.1. | M11: =VLOOKUP(L11, Работы!A:B, 2, 0) -> Стоимость аварийно-восстановительных работ, заявка по которым получена в течение рабочего времени | N11: Работы по заданию | P11: =IF(OR(L11="3.3.1.", L11="3.3.2.", L11="3.3.3.", L11="3.1.1.", L11="3.1.2.", L11="3.4.1.", L11="3.4.2."), 0, VLOOKUP(L11, Работы!$A$3:$D$184, 4, 0)) -> 0 | T11: =IF(OR(L11="3.3.1.", L11="3.3.2.", L11="3.3.3."), VLOOKUP(L11, Работы!$A$3:$D$184, 4, 0), 0) -> 0 | U11: =IF(OR(L11="3.1.1."), VLOOKUP(L11, Работы!$A$3:$D$184, 4, 0), 0) -> 3956 | V11: =IF(OR(L11="3.1.2."), VLOOKUP(L11, Работы!$A$3:$D$184, 4, 0), 0) -> 0 | Y11: =IF(OR(L11="3.2.1.", L11="3.2.2."), VLOOKUP(L11, Работы!$A$3:$D$184, 4, 0), 0) -> 0 | Z11: =IF(OR(L11="3.4.1.", L11="3.4.2."), VLOOKUP(L11, Работы!$A$3:$D$184, 4, 0), 0) -> 0 | AA11: =P11*O11+Q11*T11+R11*T11+S11*T11+U11+V11+W11*Y11+X11*Y11+Z11 -> 3956 | AE11: =AC11*AD11 -> 0 | AF11: =C11*Работы!$D$180 -> 4950.52 | AG11: =AA11+AE11+AF11+AL11+AM11 -> 9302.12 | AJ11: =AG11-AA11*AI11 -> 9302.12 | AK11: исправить километраж на "24" как в договоре | AL11: =IF(OR(E11="да"), 4040, 0) -> 0 | AM11: =IF(OR(D11="доп."), AA11*0.1, 0) -> 395.6
A12: =ROW(A12)-10 -> 2 | B12: RO2234 | C12: =VLOOKUP(B12, Расстояния!B:J, 9, 0) -> 71 | D12: =VLOOKUP(B12, Расстояния!B:K, 10, 0) -> осн. | E12: =VLOOKUP(B12, Расстояния!B:F, 5, 0) -> нет | F12: WO06718313 | G12: 46102.521 | H12: 46102.592 | I12: 46102.691 | J12: Шведков | L12: 10.3. | M12: =VLOOKUP(L12, Работы!A:B, 2, 0) -> Иные работы/услуги в отношении одного Объекта по одному обращению Заказчика в течение рабочего времени*****, независимо от количества представителей Подрядчика, участвующих в выполнении таких Работ на одном Объекте | N12: Диагностика ВЭС | O12: 1 | P12: =IF(OR(L12="3.3.1.", L12="3.3.2.", L12="3.3.3.", L12="3.1.1.", L12="3.1.2.", L12="3.4.1.", L12="3.4.2."), 0, VLOOKUP(L12, Работы!$A$3:$D$184, 4, 0)) -> 735 | T12: =IF(OR(L12="3.3.1.", L12="3.3.2.", L12="3.3.3."), VLOOKUP(L12, Работы!$A$3:$D$184, 4, 0), 0) -> 0 | U12: =IF(OR(L12="3.1.1."), VLOOKUP(L12, Работы!$A$3:$D$184, 4, 0), 0) -> 0 | V12: =IF(OR(L12="3.1.2."), VLOOKUP(L12, Работы!$A$3:$D$184, 4, 0), 0) -> 0 | Y12: =IF(OR(L12="3.2.1.", L12="3.2.2."), VLOOKUP(L12, Работы!$A$3:$D$184, 4, 0), 0) -> 0 | Z12: =IF(OR(L12="3.4.1.", L12="3.4.2."), VLOOKUP(L12, Работы!$A$3:$D$184, 4, 0), 0) -> 0 | AA12: =P12*O12+Q12*T12+R12*T12+S12*T12+U12+V12+W12*Y12+X12*Y12+Z12 -> 735 | AE12: =AC12*AD12 -> 0 | AF12: =C12*Работы!$D$180 -> 3820.51 | AG12: =AA12+AE12+AF12+AL12+AM12 -> 4555.51 | AJ12: =AG12-AA12*AI12 -> 4555.51 | AK12: удалить километраж, есть в WO06714417 | AL12: =IF(OR(E12="да"), 4040, 0) -> 0 | AM12: =IF(OR(D12="доп."), AA12*0.1, 0) -> 0
A13: =ROW(A13)-10 -> 3 | B13: RO0005 | C13: =VLOOKUP(B13, Расстояния!B:J, 9, 0) -> 61 | D13: =VLOOKUP(B13, Расстояния!B:K, 10, 0) -> осн. | E13: =VLOOKUP(B13, Расстояния!B:F, 5, 0) -> нет | F13: WO06714501 | G13: 46098.535 | H13: 46098.61 | I13: 46098.719 | J13: Шведков | L13: 3.3.1. | M13: =VLOOKUP(L13, Работы!A:B, 2, 0) -> Стоимость Аварийно-восстановительных работ по обеспечению временного электроснабжения. (Ставка применяется с 1 часа выполнения Работ, для оплаты каждых не полных суток выполнения Работ) | N13: Генерация | P13: =IF(OR(L13="3.3.1.", L13="3.3.2.", L13="3.3.3.", L13="3.1.1.", L13="3.1.2.", L13="3.4.1.", L13="3.4.2."), 0, VLOOKUP(L13, Работы!$A$3:$D$184, 4, 0)) -> 0 | Q13: =ROUNDUP((I13-H13)*24, 0) -> 3 | T13: =IF(OR(L13="3.3.1.", L13="3.3.2.", L13="3.3.3."), VLOOKUP(L13, Работы!$A$3:$D$184, 4, 0), 0) -> 903 | U13: =IF(OR(L13="3.1.1."), VLOOKUP(L13, Работы!$A$3:$D$184, 4, 0), 0) -> 0 | V13: =IF(OR(L13="3.1.2."), VLOOKUP(L13, Работы!$A$3:$D$184, 4, 0), 0) -> 0 | Y13: =IF(OR(L13="3.2.1.", L13="3.2.2."), VLOOKUP(L13, Работы!$A$3:$D$184, 4, 0), 0) -> 0 | Z13: =IF(OR(L13="3.4.1.", L13="3.4.2."), VLOOKUP(L13, Работы!$A$3:$D$184, 4, 0), 0) -> 0 | AA13: =P13*O13+Q13*T13+R13*T13+S13*T13+U13+V13+W13*Y13+X13*Y13+Z13 -> 2709 | AE13: =AC13*AD13 -> 0 | AF13: =C13*Работы!$D$180 -> 3282.41 | AG13: =AA13+AE13+AF13+AL13+AM13 -> 5991.41 | AJ13: =AG13-AA13*AI13 -> 5991.41 | AL13: =IF(OR(E13="да"), 4040, 0) -> 0 | AM13: =IF(OR(D13="доп."), AA13*0.1, 0) -> 0
A14: =ROW(A14)-10 -> 4 | B14: RO0005 | C14: 0 | D14: =VLOOKUP(B14, Расстояния!B:K, 10, 0) -> осн. | E14: =VLOOKUP(B14, Расстояния!B:F, 5, 0) -> нет | F14: WO06722800 | G14: 46106.9 | H14: 46106.912 | I14: 46106.912 | J14: Шведков | L14: 3.4.2. | M14: =VLOOKUP(L14, Работы!A:B, 2, 0) -> Стоимость отменённого вызова на Аварийно-восстановительные работы, заявка по которым получена во внерабочее время | N14: Отмена | P14: =IF(OR(L14="3.3.1.", L14="3.3.2.", L14="3.3.3.", L14="3.1.1.", L14="3.1.2.", L14="3.4.1.", L14="3.4.2."), 0, VLOOKUP(L14, Работы!$A$3:$D$184, 4, 0)) -> 0 | T14: =IF(OR(L14="3.3.1.", L14="3.3.2.", L14="3.3.3."), VLOOKUP(L14, Работы!$A$3:$D$184, 4, 0), 0) -> 0 | U14: =IF(OR(L14="3.1.1."), VLOOKUP(L14, Работы!$A$3:$D$184, 4, 0), 0) -> 0 | V14: =IF(OR(L14="3.1.2."), VLOOKUP(L14, Работы!$A$3:$D$184, 4, 0), 0) -> 0 | Y14: =IF(OR(L14="3.2.1.", L14="3.2.2."), VLOOKUP(L14, Работы!$A$3:$D$184, 4, 0), 0) -> 0 | Z14: =IF(OR(L14="3.4.1.", L14="3.4.2."), VLOOKUP(L14, Работы!$A$3:$D$184, 4, 0), 0) -> 1731 | AA14: =P14*O14+Q14*T14+R14*T14+S14*T14+U14+V14+W14*Y14+X14*Y14+Z14 -> 1731 | AE14: =AC14*AD14 -> 0 | AF14: =C14*Работы!$D$180 -> 0 | AG14: =AA14+AE14+AF14+AL14+AM14 -> 1731 | AJ14: =AG14-AA14*AI14 -> 1731 | AL14: =IF(OR(E14="да"), 4040, 0) -> 0 | AM14: =IF(OR(D14="доп."), AA14*0.1, 0) -> 0
A15: =ROW(A15)-10 -> 5 | B15: RO0005 | C15: =VLOOKUP(B15, Расстояния!B:J, 9, 0) -> 61 | D15: =VLOOKUP(B15, Расстояния!B:K, 10, 0) -> осн. | E15: =VLOOKUP(B15, Расстояния!B:F, 5, 0) -> нет | F15: WO06724161 | G15: 46107.955 | H15: 46108.026 | I15: 46111.026 | J15: Шведков | L15: 3.3.2. | M15: =VLOOKUP(L15, Работы!A:B, 2, 0) -> Стоимость Аварийно-восстановительных работ по обеспечению временного электроснабжения продолжительностью 24 часа. (Ставка применяется с 1 по 72 час выполнения Работ, для оплаты каждых полных суток (24 часа) выполнения Работ) | N15: Генерация | P15: =IF(OR(L15="3.3.1.", L15="3.3.2.", L15="3.3.3.", L15="3.1.1.", L15="3.1.2.", L15="3.4.1.", L15="3.4.2."), 0, VLOOKUP(L15, Работы!$A$3:$D$184, 4, 0)) -> 0 | R15: 3 | T15: =IF(OR(L15="3.3.1.", L15="3.3.2.", L15="3.3.3."), VLOOKUP(L15, Работы!$A$3:$D$184, 4, 0), 0) -> 32610 | U15: =IF(OR(L15="3.1.1."), VLOOKUP(L15, Работы!$A$3:$D$184, 4, 0), 0) -> 0 | V15: =IF(OR(L15="3.1.2."), VLOOKUP(L15, Работы!$A$3:$D$184, 4, 0), 0) -> 0 | Y15: =IF(OR(L15="3.2.1.", L15="3.2.2."), VLOOKUP(L15, Работы!$A$3:$D$184, 4, 0), 0) -> 0 | Z15: =IF(OR(L15="3.4.1.", L15="3.4.2."), VLOOKUP(L15, Работы!$A$3:$D$184, 4, 0), 0) -> 0 | AA15: =P15*O15+Q15*T15+R15*T15+S15*T15+U15+V15+W15*Y15+X15*Y15+Z15 -> 97830 | AE15: =AC15*AD15 -> 0 | AF15: =C15*Работы!$D$180 -> 3282.41 | AG15: =AA15+AE15+AF15+AL15+AM15 -> 101112.41 | AJ15: =AG15-AA15*AI15 -> 101112.41 | AL15: =IF(OR(E15="да"), 4040, 0) -> 0 | AM15: =IF(OR(D15="доп."), AA15*0.1, 0) -> 0
A16: =ROW(A16)-10 -> 6 | B16: RO0031 | C16: =VLOOKUP(B16, Расстояния!B:J, 9, 0) -> 67 | D16: =VLOOKUP(B16, Расстояния!B:K, 10, 0) -> осн. | E16: =VLOOKUP(B16, Расстояния!B:F, 5, 0) -> нет | H16: 46098.562 | I16: 46098.639 | J16: Черкашин | L16: 1.1. | M16: =VLOOKUP(L16, Работы!A:B, 2, 0) -> Техническое обслуживание БС | N16: Техническое обслуживание БС | O16: 1 | P16: =IF(OR(L16="3.3.1.", L16="3.3.2.", L16="3.3.3.", L16="3.1.1.", L16="3.1.2.", L16="3.4.1.", L16="3.4.2."), 0, VLOOKUP(L16, Работы!$A$3:$D$184, 4, 0)) -> 4143 | T16: =IF(OR(L16="3.3.1.", L16="3.3.2.", L16="3.3.3."), VLOOKUP(L16, Работы!$A$3:$D$184, 4, 0), 0) -> 0 | U16: =IF(OR(L16="3.1.1."), VLOOKUP(L16, Работы!$A$3:$D$184, 4, 0), 0) -> 0 | V16: =IF(OR(L16="3.1.2."), VLOOKUP(L16, Работы!$A$3:$D$184, 4, 0), 0) -> 0 | Y16: =IF(OR(L16="3.2.1.", L16="3.2.2."), VLOOKUP(L16, Работы!$A$3:$D$184, 4, 0), 0) -> 0 | Z16: =IF(OR(L16="3.4.1.", L16="3.4.2."), VLOOKUP(L16, Работы!$A$3:$D$184, 4, 0), 0) -> 0 | AA16: =P16*O16+Q16*T16+R16*T16+S16*T16+U16+V16+W16*Y16+X16*Y16+Z16 -> 4143 | AE16: =AC16*AD16 -> 0 | AF16: =C16*Работы!$D$180 -> 3605.27 | AG16: =AA16+AE16+AF16+AL16+AM16 -> 7748.27 | AJ16: =AG16-AA16*AI16 -> 7748.27 | AL16: =IF(OR(E16="да"), 4040, 0) -> 0 | AM16: =IF(OR(D16="доп."), AA16*0.1, 0) -> 0
A17: =ROW(A17)-10 -> 7 | B17: RO0034 | C17: =VLOOKUP(B17, Расстояния!B:J, 9, 0) -> 65 | D17: =VLOOKUP(B17, Расстояния!B:K, 10, 0) -> осн. | E17: =VLOOKUP(B17, Расстояния!B:F, 5, 0) -> нет | F17: WO06725961 | G17: 46110.453 | H17: 46110.531 | I17: 46110.537 | J17: Попов | L17: 3.3.1. | M17: =VLOOKUP(L17, Работы!A:B, 2, 0) -> Стоимость Аварийно-восстановительных работ по обеспечению временного электроснабжения. (Ставка применяется с 1 часа выполнения Работ, для оплаты каждых не полных суток выполнения Работ) | N17: Генерация | P17: =IF(OR(L17="3.3.1.", L17="3.3.2.", L17="3.3.3.", L17="3.1.1.", L17="3.1.2.", L17="3.4.1.", L17="3.4.2."), 0, VLOOKUP(L17, Работы!$A$3:$D$184, 4, 0)) -> 0 | Q17: =ROUNDUP((I17-H17)*24, 0) -> 1 | T17: =IF(OR(L17="3.3.1.", L17="3.3.2.", L17="3.3.3."), VLOOKUP(L17, Работы!$A$3:$D$184, 4, 0), 0) -> 903 | U17: =IF(OR(L17="3.1.1."), VLOOKUP(L17, Работы!$A$3:$D$184, 4, 0), 0) -> 0 | V17: =IF(OR(L17="3.1.2."), VLOOKUP(L17, Работы!$A$3:$D$184, 4, 0), 0) -> 0 | Y17: =IF(OR(L17="3.2.1.", L17="3.2.2."), VLOOKUP(L17, Работы!$A$3:$D$184, 4, 0), 0) -> 0 | Z17: =IF(OR(L17="3.4.1.", L17="3.4.2."), VLOOKUP(L17, Работы!$A$3:$D$184, 4, 0), 0) -> 0 | AA17: =P17*O17+Q17*T17+R17*T17+S17*T17+U17+V17+W17*Y17+X17*Y17+Z17 -> 903 | AE17: =AC17*AD17 -> 0 | AF17: =C17*Работы!$D$180 -> 3497.65 | AG17: =AA17+AE17+AF17+AL17+AM17 -> 4400.65 | AJ17: =AG17-AA17*AI17 -> 4400.65 | AL17: =IF(OR(E17="да"), 4040, 0) -> 0 | AM17: =IF(OR(D17="доп."), AA17*0.1, 0) -> 0
A18: =ROW(A18)-10 -> 8 | B18: RO0035 | C18: =VLOOKUP(B18, Расстояния!B:J, 9, 0) -> 66 | D18: =VLOOKUP(B18, Расстояния!B:K, 10, 0) -> осн. | E18: =VLOOKUP(B18, Расстояния!B:F, 5, 0) -> нет | F18: WO06724414 | G18: 46108.349 | H18: 46108.494 | I18: 46108.591 | J18: Голиков | L18: 3.1.1. | M18: =VLOOKUP(L18, Работы!A:B, 2, 0) -> Стоимость аварийно-восстановительных работ, заявка по которым получена в течение рабочего времени | N18: Переключение оптики | P18: =IF(OR(L18="3.3.1.", L18="3.3.2.", L18="3.3.3.", L18="3.1.1.", L18="3.1.2.", L18="3.4.1.", L18="3.4.2."), 0, VLOOKUP(L18, Работы!$A$3:$D$184, 4, 0)) -> 0 | T18: =IF(OR(L18="3.3.1.", L18="3.3.2.", L18="3.3.3."), VLOOKUP(L18, Работы!$A$3:$D$184, 4, 0), 0) -> 0 | U18: =IF(OR(L18="3.1.1."), VLOOKUP(L18, Работы!$A$3:$D$184, 4, 0), 0) -> 3956 | V18: =IF(OR(L18="3.1.2."), VLOOKUP(L18, Работы!$A$3:$D$184, 4, 0), 0) -> 0 | Y18: =IF(OR(L18="3.2.1.", L18="3.2.2."), VLOOKUP(L18, Работы!$A$3:$D$184, 4, 0), 0) -> 0 | Z18: =IF(OR(L18="3.4.1.", L18="3.4.2."), VLOOKUP(L18, Работы!$A$3:$D$184, 4, 0), 0) -> 0 | AA18: =P18*O18+Q18*T18+R18*T18+S18*T18+U18+V18+W18*Y18+X18*Y18+Z18 -> 3956 | AE18: =AC18*AD18 -> 0 | AF18: =C18*Работы!$D$180 -> 3551.46 | AG18: =AA18+AE18+AF18+AL18+AM18 -> 7507.46 | AJ18: =AG18-AA18*AI18 -> 7507.46 | AL18: =IF(OR(E18="да"), 4040, 0) -> 0 | AM18: =IF(OR(D18="доп."), AA18*0.1, 0) -> 0
A19: =ROW(A19)-10 -> 9 | B19: RO0035 | C19: 0 | D19: =VLOOKUP(B19, Расстояния!B:K, 10, 0) -> осн. | E19: =VLOOKUP(B19, Расстояния!B:F, 5, 0) -> нет | F19: WO06720758 | G19: 46105.469 | H19: 46108.494 | I19: 46108.591 | J19: Голиков | L19: 1.2. | M19: =VLOOKUP(L19, Работы!A:B, 2, 0) -> Диагностика и устранение дефектов АФУ сектора БС (локализация неисправности или перепуток Net Monitor'ом, проверка/ремонт разъёмов, соединительных джемперов, проверка КСВ) | N19: Проверка на перепутку | O19: 1 | P19: =IF(OR(L19="3.3.1.", L19="3.3.2.", L19="3.3.3.", L19="3.1.1.", L19="3.1.2.", L19="3.4.1.", L19="3.4.2."), 0, VLOOKUP(L19, Работы!$A$3:$D$184, 4, 0)) -> 4180 | T19: =IF(OR(L19="3.3.1.", L19="3.3.2.", L19="3.3.3."), VLOOKUP(L19, Работы!$A$3:$D$184, 4, 0), 0) -> 0 | U19: =IF(OR(L19="3.1.1."), VLOOKUP(L19, Работы!$A$3:$D$184, 4, 0), 0) -> 0 | V19: =IF(OR(L19="3.1.2."), VLOOKUP(L19, Работы!$A$3:$D$184, 4, 0), 0) -> 0 | Y19: =IF(OR(L19="3.2.1.", L19="3.2.2."), VLOOKUP(L19, Работы!$A$3:$D$184, 4, 0), 0) -> 0 | Z19: =IF(OR(L19="3.4.1.", L19="3.4.2."), VLOOKUP(L19, Работы!$A$3:$D$184, 4, 0), 0) -> 0 | AA19: =P19*O19+Q19*T19+R19*T19+S19*T19+U19+V19+W19*Y19+X19*Y19+Z19 -> 4180 | AE19: =AC19*AD19 -> 0 | AF19: =C19*Работы!$D$180 -> 0 | AG19: =AA19+AE19+AF19+AL19+AM19 -> 4180 | AJ19: =AG19-AA19*AI19 -> 4180 | AL19: =IF(OR(E19="да"), 4040, 0) -> 0 | AM19: =IF(OR(D19="доп."), AA19*0.1, 0) -> 0
A20: =ROW(A20)-10 -> 10 | B20: RO0038 | C20: 60 | D20: =VLOOKUP(B20, Расстояния!B:K, 10, 0) -> осн. | E20: =VLOOKUP(B20, Расстояния!B:F, 5, 0) -> нет | F20: WO06720033 | G20: 46105.026 | H20: 46105.101 | I20: 46105.101 | J20: Попов | L20: 3.4.2. | M20: =VLOOKUP(L20, Работы!A:B, 2, 0) -> Стоимость отменённого вызова на Аварийно-восстановительные работы, заявка по которым получена во внерабочее время | N20: Отмена | P20: =IF(OR(L20="3.3.1.", L20="3.3.2.", L20="3.3.3.", L20="3.1.1.", L20="3.1.2.", L20="3.4.1.", L20="3.4.2."), 0, VLOOKUP(L20, Работы!$A$3:$D$184, 4, 0)) -> 0 | T20: =IF(OR(L20="3.3.1.", L20="3.3.2.", L20="3.3.3."), VLOOKUP(L20, Работы!$A$3:$D$184, 4, 0), 0) -> 0 | U20: =IF(OR(L20="3.1.1."), VLOOKUP(L20, Работы!$A$3:$D$184, 4, 0), 0) -> 0 | V20: =IF(OR(L20="3.1.2."), VLOOKUP(L20, Работы!$A$3:$D$184, 4, 0), 0) -> 0 | Y20: =IF(OR(L20="3.2.1.", L20="3.2.2."), VLOOKUP(L20, Работы!$A$3:$D$184, 4, 0), 0) -> 0 | Z20: =IF(OR(L20="3.4.1.", L20="3.4.2."), VLOOKUP(L20, Работы!$A$3:$D$184, 4, 0), 0) -> 1731 | AA20: =P20*O20+Q20*T20+R20*T20+S20*T20+U20+V20+W20*Y20+X20*Y20+Z20 -> 1731 | AE20: =AC20*AD20 -> 0 | AF20: =C20*Работы!$D$180 -> 3228.6 | AG20: =AA20+AE20+AF20+AL20+AM20 -> 4959.6 | AJ20: =AG20-AA20*AI20 -> 4959.6 | AL20: =IF(OR(E20="да"), 4040, 0) -> 0 | AM20: =IF(OR(D20="доп."), AA20*0.1, 0) -> 0
A21: =ROW(A21)-10 -> 11 | B21: RO0045 | C21: =VLOOKUP(B21, Расстояния!B:J, 9, 0) -> 69 | D21: =VLOOKUP(B21, Расстояния!B:K, 10, 0) -> осн. | E21: =VLOOKUP(B21, Расстояния!B:F, 5, 0) -> нет | F21: WO06724537 | G21: 46108.403 | H21: 46108.488 | I21: 46108.741 | J21: Попов | L21: 3.3.1. | M21: =VLOOKUP(L21, Работы!A:B, 2, 0) -> Стоимость Аварийно-восстановительных работ по обеспечению временного электроснабжения. (Ставка применяется с 1 часа выполнения Работ, для оплаты каждых не полных суток выполнения Работ) | N21: Генерация | P21: =IF(OR(L21="3.3.1.", L21="3.3.2.", L21="3.3.3.", L21="3.1.1.", L21="3.1.2.", L21="3.4.1.", L21="3.4.2."), 0, VLOOKUP(L21, Работы!$A$3:$D$184, 4, 0)) -> 0 | Q21: =ROUNDUP((I21-H21)*24, 0) -> 7 | T21: =IF(OR(L21="3.3.1.", L21="3.3.2.", L21="3.3.3."), VLOOKUP(L21, Работы!$A$3:$D$184, 4, 0), 0) -> 903 | U21: =IF(OR(L21="3.1.1."), VLOOKUP(L21, Работы!$A$3:$D$184, 4, 0), 0) -> 0 | V21: =IF(OR(L21="3.1.2."), VLOOKUP(L21, Работы!$A$3:$D$184, 4, 0), 0) -> 0 | Y21: =IF(OR(L21="3.2.1.", L21="3.2.2."), VLOOKUP(L21, Работы!$A$3:$D$184, 4, 0), 0) -> 0 | Z21: =IF(OR(L21="3.4.1.", L21="3.4.2."), VLOOKUP(L21, Работы!$A$3:$D$184, 4, 0), 0) -> 0 | AA21: =P21*O21+Q21*T21+R21*T21+S21*T21+U21+V21+W21*Y21+X21*Y21+Z21 -> 6321 | AE21: =AC21*AD21 -> 0 | AF21: =C21*Работы!$D$180 -> 3712.89 | AG21: =AA21+AE21+AF21+AL21+AM21 -> 10033.89 | AJ21: =AG21-AA21*AI21 -> 10033.89 | AL21: =IF(OR(E21="да"), 4040, 0) -> 0 | AM21: =IF(OR(D21="доп."), AA21*0.1, 0) -> 0
A22: =ROW(A22)-10 -> 12 | B22: RO0045 | C22: =VLOOKUP(B22, Расстояния!B:J, 9, 0) -> 69 | D22: =VLOOKUP(B22, Расстояния!B:K, 10, 0) -> осн. | E22: =VLOOKUP(B22, Расстояния!B:F, 5, 0) -> нет | F22: WO06713613 | G22: 46097.7 | H22: 46097.777 | I22: 46098.078 | J22: Шведков | L22: 3.3.1. | M22: =VLOOKUP(L22, Работы!A:B, 2, 0) -> Стоимость Аварийно-восстановительных работ по обеспечению временного электроснабжения. (Ставка применяется с 1 часа выполнения Работ, для оплаты каждых не полных суток выполнения Работ) | N22: Генерация | P22: =IF(OR(L22="3.3.1.", L22="3.3.2.", L22="3.3.3.", L22="3.1.1.", L22="3.1.2.", L22="3.4.1.", L22="3.4.2."), 0, VLOOKUP(L22, Работы!$A$3:$D$184, 4, 0)) -> 0 | Q22: =ROUNDUP((I22-H22)*24, 0) -> 8 | T22: =IF(OR(L22="3.3.1.", L22="3.3.2.", L22="3.3.3."), VLOOKUP(L22, Работы!$A$3:$D$184, 4, 0), 0) -> 903 | U22: =IF(OR(L22="3.1.1."), VLOOKUP(L22, Работы!$A$3:$D$184, 4, 0), 0) -> 0 | V22: =IF(OR(L22="3.1.2."), VLOOKUP(L22, Работы!$A$3:$D$184, 4, 0), 0) -> 0 | Y22: =IF(OR(L22="3.2.1.", L22="3.2.2."), VLOOKUP(L22, Работы!$A$3:$D$184, 4, 0), 0) -> 0 | Z22: =IF(OR(L22="3.4.1.", L22="3.4.2."), VLOOKUP(L22, Работы!$A$3:$D$184, 4, 0), 0) -> 0 | AA22: =P22*O22+Q22*T22+R22*T22+S22*T22+U22+V22+W22*Y22+X22*Y22+Z22 -> 7224 | AE22: =AC22*AD22 -> 0 | AF22: =C22*Работы!$D$180 -> 3712.89 | AG22: =AA22+AE22+AF22+AL22+AM22 -> 10936.89 | AJ22: =AG22-AA22*AI22 -> 10936.89 | AL22: =IF(OR(E22="да"), 4040, 0) -> 0 | AM22: =IF(OR(D22="доп."), AA22*0.1, 0) -> 0
A23: =ROW(A23)-10 -> 13 | B23: RO0047 | C23: =VLOOKUP(B23, Расстояния!B:J, 9, 0) -> 64 | D23: =VLOOKUP(B23, Расстояния!B:K, 10, 0) -> осн. | E23: =VLOOKUP(B23, Расстояния!B:F, 5, 0) -> нет | F23: WO06697153 | G23: 46078.463 | H23: 46080.458 | I23: 46080.479 | J23: Пастушенко | L23: 10.3. | M23: =VLOOKUP(L23, Работы!A:B, 2, 0) -> Иные работы/услуги в отношении одного Объекта по одному обращению Заказчика в течение рабочего времени*****, независимо от количества представителей Подрядчика, участвующих в выполнении таких Работ на одном Объекте | N23: Работы по заданию. Осмотр БС. | O23: 1 | P23: =IF(OR(L23="3.3.1.", L23="3.3.2.", L23="3.3.3.", L23="3.1.1.", L23="3.1.2.", L23="3.4.1.", L23="3.4.2."), 0, VLOOKUP(L23, Работы!$A$3:$D$184, 4, 0)) -> 735 | T23: =IF(OR(L23="3.3.1.", L23="3.3.2.", L23="3.3.3."), VLOOKUP(L23, Работы!$A$3:$D$184, 4, 0), 0) -> 0 | U23: =IF(OR(L23="3.1.1."), VLOOKUP(L23, Работы!$A$3:$D$184, 4, 0), 0) -> 0 | V23: =IF(OR(L23="3.1.2."), VLOOKUP(L23, Работы!$A$3:$D$184, 4, 0), 0) -> 0 | Y23: =IF(OR(L23="3.2.1.", L23="3.2.2."), VLOOKUP(L23, Работы!$A$3:$D$184, 4, 0), 0) -> 0 | Z23: =IF(OR(L23="3.4.1.", L23="3.4.2."), VLOOKUP(L23, Работы!$A$3:$D$184, 4, 0), 0) -> 0 | AA23: =P23*O23+Q23*T23+R23*T23+S23*T23+U23+V23+W23*Y23+X23*Y23+Z23 -> 735 | AE23: =AC23*AD23 -> 0 | AF23: =C23*Работы!$D$180 -> 3443.84 | AG23: =AA23+AE23+AF23+AL23+AM23 -> 4178.84 | AJ23: =AG23-AA23*AI23 -> 4178.84 | AL23: =IF(OR(E23="да"), 4040, 0) -> 0 | AM23: =IF(OR(D23="доп."), AA23*0.1, 0) -> 0
A24: =ROW(A24)-10 -> 14 | B24: RO2241 | C24: =VLOOKUP(B24, Расстояния!B:J, 9, 0) -> 52 | D24: =VLOOKUP(B24, Расстояния!B:K, 10, 0) -> осн. | E24: =VLOOKUP(B24, Расстояния!B:F, 5, 0) -> нет | F24: WO06713841 | G24: 46098.169 | H24: 46098.244 | I24: 46098.402 | J24: Пастушенко | L24: 3.3.1. | M24: =VLOOKUP(L24, Работы!A:B, 2, 0) -> Стоимость Аварийно-восстановительных работ по обеспечению временного электроснабжения. (Ставка применяется с 1 часа выполнения Работ, для оплаты каждых не полных суток выполнения Работ) | N24: Генерация | P24: =IF(OR(L24="3.3.1.", L24="3.3.2.", L24="3.3.3.", L24="3.1.1.", L24="3.1.2.", L24="3.4.1.", L24="3.4.2."), 0, VLOOKUP(L24, Работы!$A$3:$D$184, 4, 0)) -> 0 | Q24: =ROUNDUP((I24-H24)*24, 0) -> 4 | T24: =IF(OR(L24="3.3.1.", L24="3.3.2.", L24="3.3.3."), VLOOKUP(L24, Работы!$A$3:$D$184, 4, 0), 0) -> 903 | U24: =IF(OR(L24="3.1.1."), VLOOKUP(L24, Работы!$A$3:$D$184, 4, 0), 0) -> 0 | V24: =IF(OR(L24="3.1.2."), VLOOKUP(L24, Работы!$A$3:$D$184, 4, 0), 0) -> 0 | Y24: =IF(OR(L24="3.2.1.", L24="3.2.2."), VLOOKUP(L24, Работы!$A$3:$D$184, 4, 0), 0) -> 0 | Z24: =IF(OR(L24="3.4.1.", L24="3.4.2."), VLOOKUP(L24, Работы!$A$3:$D$184, 4, 0), 0) -> 0 | AA24: =P24*O24+Q24*T24+R24*T24+S24*T24+U24+V24+W24*Y24+X24*Y24+Z24 -> 3612 | AE24: =AC24*AD24 -> 0 | AF24: =C24*Работы!$D$180 -> 2798.12 | AG24: =AA24+AE24+AF24+AL24+AM24 -> 6410.12 | AJ24: =AG24-AA24*AI24 -> 6410.12 | AL24: =IF(OR(E24="да"), 4040, 0) -> 0 | AM24: =IF(OR(D24="доп."), AA24*0.1, 0) -> 0
A25: =ROW(A25)-10 -> 15 | B25: RO0065 | C25: =VLOOKUP(B25, Расстояния!B:J, 9, 0) -> 70 | D25: =VLOOKUP(B25, Расстояния!B:K, 10, 0) -> осн. | E25: =VLOOKUP(B25, Расстояния!B:F, 5, 0) -> нет | F25: WO06720860 | G25: 46105.497 | H25: 46106.617 | I25: 46106.644 | J25: Голиков | L25: 1.2. | M25: =VLOOKUP(L25, Работы!A:B, 2, 0) -> Диагностика и устранение дефектов АФУ сектора БС (локализация неисправности или перепуток Net Monitor'ом, проверка/ремонт разъёмов, соединительных джемперов, проверка КСВ) | N25: Проверка на перепутку | O25: 1 | P25: =IF(OR(L25="3.3.1.", L25="3.3.2.", L25="3.3.3.", L25="3.1.1.", L25="3.1.2.", L25="3.4.1.", L25="3.4.2."), 0, VLOOKUP(L25, Работы!$A$3:$D$184, 4, 0)) -> 4180 | T25: =IF(OR(L25="3.3.1.", L25="3.3.2.", L25="3.3.3."), VLOOKUP(L25, Работы!$A$3:$D$184, 4, 0), 0) -> 0 | U25: =IF(OR(L25="3.1.1."), VLOOKUP(L25, Работы!$A$3:$D$184, 4, 0), 0) -> 0 | V25: =IF(OR(L25="3.1.2."), VLOOKUP(L25, Работы!$A$3:$D$184, 4, 0), 0) -> 0 | Y25: =IF(OR(L25="3.2.1.", L25="3.2.2."), VLOOKUP(L25, Работы!$A$3:$D$184, 4, 0), 0) -> 0 | Z25: =IF(OR(L25="3.4.1.", L25="3.4.2."), VLOOKUP(L25, Работы!$A$3:$D$184, 4, 0), 0) -> 0 | AA25: =P25*O25+Q25*T25+R25*T25+S25*T25+U25+V25+W25*Y25+X25*Y25+Z25 -> 4180 | AE25: =AC25*AD25 -> 0 | AF25: =C25*Работы!$D$180 -> 3766.7 | AG25: =AA25+AE25+AF25+AL25+AM25 -> 7946.7 | AJ25: =AG25-AA25*AI25 -> 7946.7 | AL25: =IF(OR(E25="да"), 4040, 0) -> 0 | AM25: =IF(OR(D25="доп."), AA25*0.1, 0) -> 0
A26: =ROW(A26)-10 -> 16 | B26: RO0065 | C26: 0 | D26: =VLOOKUP(B26, Расстояния!B:K, 10, 0) -> осн. | E26: =VLOOKUP(B26, Расстояния!B:F, 5, 0) -> нет | F26: WO06722580 | G26: 45741.633 | H26: 46106.617 | I26: 46106.644 | J26: Голиков | L26: 10.3. | M26: =VLOOKUP(L26, Работы!A:B, 2, 0) -> Иные работы/услуги в отношении одного Объекта по одному обращению Заказчика в течение рабочего времени*****, независимо от количества представителей Подрядчика, участвующих в выполнении таких Работ на одном Объекте | N26: Чистка фильтров | O26: 1 | P26: =IF(OR(L26="3.3.1.", L26="3.3.2.", L26="3.3.3.", L26="3.1.1.", L26="3.1.2.", L26="3.4.1.", L26="3.4.2."), 0, VLOOKUP(L26, Работы!$A$3:$D$184, 4, 0)) -> 735 | T26: =IF(OR(L26="3.3.1.", L26="3.3.2.", L26="3.3.3."), VLOOKUP(L26, Работы!$A$3:$D$184, 4, 0), 0) -> 0 | U26: =IF(OR(L26="3.1.1."), VLOOKUP(L26, Работы!$A$3:$D$184, 4, 0), 0) -> 0 | V26: =IF(OR(L26="3.1.2."), VLOOKUP(L26, Работы!$A$3:$D$184, 4, 0), 0) -> 0 | Y26: =IF(OR(L26="3.2.1.", L26="3.2.2."), VLOOKUP(L26, Работы!$A$3:$D$184, 4, 0), 0) -> 0 | Z26: =IF(OR(L26="3.4.1.", L26="3.4.2."), VLOOKUP(L26, Работы!$A$3:$D$184, 4, 0), 0) -> 0 | AA26: =P26*O26+Q26*T26+R26*T26+S26*T26+U26+V26+W26*Y26+X26*Y26+Z26 -> 735 | AE26: =AC26*AD26 -> 0 | AF26: =C26*Работы!$D$180 -> 0 | AG26: =AA26+AE26+AF26+AL26+AM26 -> 735 | AJ26: =AG26-AA26*AI26 -> 735 | AL26: =IF(OR(E26="да"), 4040, 0) -> 0 | AM26: =IF(OR(D26="доп."), AA26*0.1, 0) -> 0
A27: =ROW(A27)-10 -> 17 | B27: RO0085 | C27: =VLOOKUP(B27, Расстояния!B:J, 9, 0) -> 67 | D27: =VLOOKUP(B27, Расстояния!B:K, 10, 0) -> осн. | E27: =VLOOKUP(B27, Расстояния!B:F, 5, 0) -> нет | F27: WO06724695 | G27: 46108.454 | H27: 46108.485 | I27: 46108.72 | J27: Шведков | L27: 3.3.1. | M27: =VLOOKUP(L27, Работы!A:B, 2, 0) -> Стоимость Аварийно-восстановительных работ по обеспечению временного электроснабжения. (Ставка применяется с 1 часа выполнения Работ, для оплаты каждых не полных суток выполнения Работ) | N27: Генерация | P27: =IF(OR(L27="3.3.1.", L27="3.3.2.", L27="3.3.3.", L27="3.1.1.", L27="3.1.2.", L27="3.4.1.", L27="3.4.2."), 0, VLOOKUP(L27, Работы!$A$3:$D$184, 4, 0)) -> 0 | Q27: =ROUNDUP((I27-H27)*24, 0) -> 6 | T27: =IF(OR(L27="3.3.1.", L27="3.3.2.", L27="3.3.3."), VLOOKUP(L27, Работы!$A$3:$D$184, 4, 0), 0) -> 903 | U27: =IF(OR(L27="3.1.1."), VLOOKUP(L27, Работы!$A$3:$D$184, 4, 0), 0) -> 0 | V27: =IF(OR(L27="3.1.2."), VLOOKUP(L27, Работы!$A$3:$D$184, 4, 0), 0) -> 0 | Y27: =IF(OR(L27="3.2.1.", L27="3.2.2."), VLOOKUP(L27, Работы!$A$3:$D$184, 4, 0), 0) -> 0 | Z27: =IF(OR(L27="3.4.1.", L27="3.4.2."), VLOOKUP(L27, Работы!$A$3:$D$184, 4, 0), 0) -> 0 | AA27: =P27*O27+Q27*T27+R27*T27+S27*T27+U27+V27+W27*Y27+X27*Y27+Z27 -> 5418 | AE27: =AC27*AD27 -> 0 | AF27: =C27*Работы!$D$180 -> 3605.27 | AG27: =AA27+AE27+AF27+AL27+AM27 -> 9023.27 | AJ27: =AG27-AA27*AI27 -> 9023.27 | AL27: =IF(OR(E27="да"), 4040, 0) -> 0 | AM27: =IF(OR(D27="доп."), AA27*0.1, 0) -> 0
A28: =ROW(A28)-10 -> 18 | B28: RO0098 | C28: =VLOOKUP(B28, Расстояния!B:J, 9, 0) -> 66 | D28: =VLOOKUP(B28, Расстояния!B:K, 10, 0) -> осн. | E28: =VLOOKUP(B28, Расстояния!B:F, 5, 0) -> нет | H28: 46100.592 | I28: 46100.629 | J28: Ахундов | L28: 1.1. | M28: =VLOOKUP(L28, Работы!A:B, 2, 0) -> Техническое обслуживание БС | N28: Техническое обслуживание БС | O28: 1 | P28: =IF(OR(L28="3.3.1.", L28="3.3.2.", L28="3.3.3.", L28="3.1.1.", L28="3.1.2.", L28="3.4.1.", L28="3.4.2."), 0, VLOOKUP(L28, Работы!$A$3:$D$184, 4, 0)) -> 4143 | T28: =IF(OR(L28="3.3.1.", L28="3.3.2.", L28="3.3.3."), VLOOKUP(L28, Работы!$A$3:$D$184, 4, 0), 0) -> 0 | U28: =IF(OR(L28="3.1.1."), VLOOKUP(L28, Работы!$A$3:$D$184, 4, 0), 0) -> 0 | V28: =IF(OR(L28="3.1.2."), VLOOKUP(L28, Работы!$A$3:$D$184, 4, 0), 0) -> 0 | Y28: =IF(OR(L28="3.2.1.", L28="3.2.2."), VLOOKUP(L28, Работы!$A$3:$D$184, 4, 0), 0) -> 0 | Z28: =IF(OR(L28="3.4.1.", L28="3.4.2."), VLOOKUP(L28, Работы!$A$3:$D$184, 4, 0), 0) -> 0 | AA28: =P28*O28+Q28*T28+R28*T28+S28*T28+U28+V28+W28*Y28+X28*Y28+Z28 -> 4143 | AE28: =AC28*AD28 -> 0 | AF28: =C28*Работы!$D$180 -> 3551.46 | AG28: =AA28+AE28+AF28+AL28+AM28 -> 7694.46 | AJ28: =AG28-AA28*AI28 -> 7694.46 | AL28: =IF(OR(E28="да"), 4040, 0) -> 0 | AM28: =IF(OR(D28="доп."), AA28*0.1, 0) -> 0
A29: =ROW(A29)-10 -> 19 | B29: RO0099 | C29: =VLOOKUP(B29, Расстояния!B:J, 9, 0) -> 68 | D29: =VLOOKUP(B29, Расстояния!B:K, 10, 0) -> осн. | E29: =VLOOKUP(B29, Расстояния!B:F, 5, 0) -> нет | F29: WO06708638 | G29: 46091.592 | H29: 46092.388 | I29: 46092.471 | J29: Жадько | L29: 1.13. | M29: =VLOOKUP(L29, Работы!A:B, 2, 0) -> Изменение механического угла наклона или азимута одной антенны | N29: Изменение механического угла наклона одной антенны | O29: 1 | P29: =IF(OR(L29="3.3.1.", L29="3.3.2.", L29="3.3.3.", L29="3.1.1.", L29="3.1.2.", L29="3.4.1.", L29="3.4.2."), 0, VLOOKUP(L29, Работы!$A$3:$D$184, 4, 0)) -> 2085 | T29: =IF(OR(L29="3.3.1.", L29="3.3.2.", L29="3.3.3."), VLOOKUP(L29, Работы!$A$3:$D$184, 4, 0), 0) -> 0 | U29: =IF(OR(L29="3.1.1."), VLOOKUP(L29, Работы!$A$3:$D$184, 4, 0), 0) -> 0 | V29: =IF(OR(L29="3.1.2."), VLOOKUP(L29, Работы!$A$3:$D$184, 4, 0), 0) -> 0 | Y29: =IF(OR(L29="3.2.1.", L29="3.2.2."), VLOOKUP(L29, Работы!$A$3:$D$184, 4, 0), 0) -> 0 | Z29: =IF(OR(L29="3.4.1.", L29="3.4.2."), VLOOKUP(L29, Работы!$A$3:$D$184, 4, 0), 0) -> 0 | AA29: =P29*O29+Q29*T29+R29*T29+S29*T29+U29+V29+W29*Y29+X29*Y29+Z29 -> 2085 | AE29: =AC29*AD29 -> 0 | AF29: =C29*Работы!$D$180 -> 3659.08 | AG29: =AA29+AE29+AF29+AL29+AM29 -> 5744.08 | AJ29: =AG29-AA29*AI29 -> 5744.08 | AL29: =IF(OR(E29="да"), 4040, 0) -> 0 | AM29: =IF(OR(D29="доп."), AA29*0.1, 0) -> 0
A30: =ROW(A30)-10 -> 20 | B30: RO0099 | C30: 0 | D30: =VLOOKUP(B30, Расстояния!B:K, 10, 0) -> осн. | E30: =VLOOKUP(B30, Расстояния!B:F, 5, 0) -> нет | F30: WO06708638 | G30: 46091.592 | H30: 46092.388 | I30: 46092.471 | J30: Жадько | L30: 1.13. | M30: =VLOOKUP(L30, Работы!A:B, 2, 0) -> Изменение механического угла наклона или азимута одной антенны | N30: Изменение азимута одной антенны | O30: 1 | P30: =IF(OR(L30="3.3.1.", L30="3.3.2.", L30="3.3.3.", L30="3.1.1.", L30="3.1.2.", L30="3.4.1.", L30="3.4.2."), 0, VLOOKUP(L30, Работы!$A$3:$D$184, 4, 0)) -> 2085 | T30: =IF(OR(L30="3.3.1.", L30="3.3.2.", L30="3.3.3."), VLOOKUP(L30, Работы!$A$3:$D$184, 4, 0), 0) -> 0 | U30: =IF(OR(L30="3.1.1."), VLOOKUP(L30, Работы!$A$3:$D$184, 4, 0), 0) -> 0 | V30: =IF(OR(L30="3.1.2."), VLOOKUP(L30, Работы!$A$3:$D$184, 4, 0), 0) -> 0 | Y30: =IF(OR(L30="3.2.1.", L30="3.2.2."), VLOOKUP(L30, Работы!$A$3:$D$184, 4, 0), 0) -> 0 | Z30: =IF(OR(L30="3.4.1.", L30="3.4.2."), VLOOKUP(L30, Работы!$A$3:$D$184, 4, 0), 0) -> 0 | AA30: =P30*O30+Q30*T30+R30*T30+S30*T30+U30+V30+W30*Y30+X30*Y30+Z30 -> 2085 | AE30: =AC30*AD30 -> 0 | AF30: =C30*Работы!$D$180 -> 0 | AG30: =AA30+AE30+AF30+AL30+AM30 -> 2085 | AJ30: =AG30-AA30*AI30 -> 2085 | AL30: =IF(OR(E30="да"), 4040, 0) -> 0 | AM30: =IF(OR(D30="доп."), AA30*0.1, 0) -> 0
A31: =ROW(A31)-10 -> 21 | B31: RO0099 | C31: 0 | D31: =VLOOKUP(B31, Расстояния!B:K, 10, 0) -> осн. | E31: =VLOOKUP(B31, Расстояния!B:F, 5, 0) -> нет | F31: WO06708638 | G31: 46091.592 | H31: 46092.388 | I31: 46092.471 | J31: Жадько | T31: =IF(OR(L31="3.3.1.", L31="3.3.2.", L31="3.3.3."), VLOOKUP(L31, Работы!$A$3:$D$184, 4, 0), 0) -> 0 | U31: =IF(OR(L31="3.1.1."), VLOOKUP(L31, Работы!$A$3:$D$184, 4, 0), 0) -> 0 | V31: =IF(OR(L31="3.1.2."), VLOOKUP(L31, Работы!$A$3:$D$184, 4, 0), 0) -> 0 | Y31: =IF(OR(L31="3.2.1.", L31="3.2.2."), VLOOKUP(L31, Работы!$A$3:$D$184, 4, 0), 0) -> 0 | Z31: =IF(OR(L31="3.4.1.", L31="3.4.2."), VLOOKUP(L31, Работы!$A$3:$D$184, 4, 0), 0) -> 0 | AA31: =P31*O31+Q31*T31+R31*T31+S31*T31+U31+V31+W31*Y31+X31*Y31+Z31 -> 0 | AB31: Альп-работы | AC31: 1 | AD31: 18000 | AE31: =AC31*AD31 -> 18000 | AF31: =C31*Работы!$D$180 -> 0 | AG31: =AA31+AE31+AF31+AL31+AM31 -> 18000 | AJ31: =AG31-AA31*AI31 -> 18000 | AL31: =IF(OR(E31="да"), 4040, 0) -> 0 | AM31: =IF(OR(D31="доп."), AA31*0.1, 0) -> 0
A32: =ROW(A32)-10 -> 22 | B32: RO2901 | C32: =VLOOKUP(B32, Расстояния!B:J, 9, 0) -> 65 | D32: =VLOOKUP(B32, Расстояния!B:K, 10, 0) -> осн. | E32: =VLOOKUP(B32, Расстояния!B:F, 5, 0) -> нет | F32: WO06714405 | G32: 46098.492 | H32: 46098.541 | I32: 46098.731 | J32: Пастушенко | L32: 3.3.1. | M32: =VLOOKUP(L32, Работы!A:B, 2, 0) -> Стоимость Аварийно-восстановительных работ по обеспечению временного электроснабжения. (Ставка применяется с 1 часа выполнения Работ, для оплаты каждых не полных суток выполнения Работ) | N32: Генерация | P32: =IF(OR(L32="3.3.1.", L32="3.3.2.", L32="3.3.3.", L32="3.1.1.", L32="3.1.2.", L32="3.4.1.", L32="3.4.2."), 0, VLOOKUP(L32, Работы!$A$3:$D$184, 4, 0)) -> 0 | Q32: =ROUNDUP((I32-H32)*24, 0) -> 5 | T32: =IF(OR(L32="3.3.1.", L32="3.3.2.", L32="3.3.3."), VLOOKUP(L32, Работы!$A$3:$D$184, 4, 0), 0) -> 903 | U32: =IF(OR(L32="3.1.1."), VLOOKUP(L32, Работы!$A$3:$D$184, 4, 0), 0) -> 0 | V32: =IF(OR(L32="3.1.2."), VLOOKUP(L32, Работы!$A$3:$D$184, 4, 0), 0) -> 0 | Y32: =IF(OR(L32="3.2.1.", L32="3.2.2."), VLOOKUP(L32, Работы!$A$3:$D$184, 4, 0), 0) -> 0 | Z32: =IF(OR(L32="3.4.1.", L32="3.4.2."), VLOOKUP(L32, Работы!$A$3:$D$184, 4, 0), 0) -> 0 | AA32: =P32*O32+Q32*T32+R32*T32+S32*T32+U32+V32+W32*Y32+X32*Y32+Z32 -> 4515 | AE32: =AC32*AD32 -> 0 | AF32: =C32*Работы!$D$180 -> 3497.65 | AG32: =AA32+AE32+AF32+AL32+AM32 -> 8012.65 | AJ32: =AG32-AA32*AI32 -> 8012.65 | AL32: =IF(OR(E32="да"), 4040, 0) -> 0 | AM32: =IF(OR(D32="доп."), AA32*0.1, 0) -> 0
A33: =ROW(A33)-10 -> 23 | B33: RO2901 | C33: =VLOOKUP(B33, Расстояния!B:J, 9, 0) -> 65 | D33: =VLOOKUP(B33, Расстояния!B:K, 10, 0) -> осн. | E33: =VLOOKUP(B33, Расстояния!B:F, 5, 0) -> нет | F33: WO06715685 | G33: 46099.56 | H33: 46099.601 | I33: 46099.615 | J33: Пастушенко | L33: 3.3.1. | M33: =VLOOKUP(L33, Работы!A:B, 2, 0) -> Стоимость Аварийно-восстановительных работ по обеспечению временного электроснабжения. (Ставка применяется с 1 часа выполнения Работ, для оплаты каждых не полных суток выполнения Работ) | N33: Генерация | P33: =IF(OR(L33="3.3.1.", L33="3.3.2.", L33="3.3.3.", L33="3.1.1.", L33="3.1.2.", L33="3.4.1.", L33="3.4.2."), 0, VLOOKUP(L33, Работы!$A$3:$D$184, 4, 0)) -> 0 | Q33: =ROUNDUP((I33-H33)*24, 0) -> 1 | T33: =IF(OR(L33="3.3.1.", L33="3.3.2.", L33="3.3.3."), VLOOKUP(L33, Работы!$A$3:$D$184, 4, 0), 0) -> 903 | U33: =IF(OR(L33="3.1.1."), VLOOKUP(L33, Работы!$A$3:$D$184, 4, 0), 0) -> 0 | V33: =IF(OR(L33="3.1.2."), VLOOKUP(L33, Работы!$A$3:$D$184, 4, 0), 0) -> 0 | Y33: =IF(OR(L33="3.2.1.", L33="3.2.2."), VLOOKUP(L33, Работы!$A$3:$D$184, 4, 0), 0) -> 0 | Z33: =IF(OR(L33="3.4.1.", L33="3.4.2."), VLOOKUP(L33, Работы!$A$3:$D$184, 4, 0), 0) -> 0 | AA33: =P33*O33+Q33*T33+R33*T33+S33*T33+U33+V33+W33*Y33+X33*Y33+Z33 -> 903 | AE33: =AC33*AD33 -> 0 | AF33: =C33*Работы!$D$180 -> 3497.65 | AG33: =AA33+AE33+AF33+AL33+AM33 -> 4400.65 | AJ33: =AG33-AA33*AI33 -> 4400.65 | AL33: =IF(OR(E33="да"), 4040, 0) -> 0 | AM33: =IF(OR(D33="доп."), AA33*0.1, 0) -> 0
A34: =ROW(A34)-10 -> 24 | B34: RO0135 | C34: =VLOOKUP(B34, Расстояния!B:J, 9, 0) -> 66 | D34: =VLOOKUP(B34, Расстояния!B:K, 10, 0) -> осн. | E34: =VLOOKUP(B34, Расстояния!B:F, 5, 0) -> нет | F34: WO06724458 | G34: 46108.376 | H34: 46108.414 | I34: 46108.761 | J34: Голиков | L34: 3.1.1. | M34: =VLOOKUP(L34, Работы!A:B, 2, 0) -> Стоимость аварийно-восстановительных работ, заявка по которым получена в течение рабочего времени | N34: Чистка передатчика | P34: =IF(OR(L34="3.3.1.", L34="3.3.2.", L34="3.3.3.", L34="3.1.1.", L34="3.1.2.", L34="3.4.1.", L34="3.4.2."), 0, VLOOKUP(L34, Работы!$A$3:$D$184, 4, 0)) -> 0 | T34: =IF(OR(L34="3.3.1.", L34="3.3.2.", L34="3.3.3."), VLOOKUP(L34, Работы!$A$3:$D$184, 4, 0), 0) -> 0 | U34: =IF(OR(L34="3.1.1."), VLOOKUP(L34, Работы!$A$3:$D$184, 4, 0), 0) -> 3956 | V34: =IF(OR(L34="3.1.2."), VLOOKUP(L34, Работы!$A$3:$D$184, 4, 0), 0) -> 0 | Y34: =IF(OR(L34="3.2.1.", L34="3.2.2."), VLOOKUP(L34, Работы!$A$3:$D$184, 4, 0), 0) -> 0 | Z34: =IF(OR(L34="3.4.1.", L34="3.4.2."), VLOOKUP(L34, Работы!$A$3:$D$184, 4, 0), 0) -> 0 | AA34: =P34*O34+Q34*T34+R34*T34+S34*T34+U34+V34+W34*Y34+X34*Y34+Z34 -> 3956 | AE34: =AC34*AD34 -> 0 | AF34: =C34*Работы!$D$180 -> 3551.46 | AG34: =AA34+AE34+AF34+AL34+AM34 -> 7507.46 | AJ34: =AG34-AA34*AI34 -> 7507.46 | AL34: =IF(OR(E34="да"), 4040, 0) -> 0 | AM34: =IF(OR(D34="доп."), AA34*0.1, 0) -> 0
A35: =ROW(A35)-10 -> 25 | B35: RO0174 | C35: =VLOOKUP(B35, Расстояния!B:J, 9, 0) -> 67 | D35: =VLOOKUP(B35, Расстояния!B:K, 10, 0) -> осн. | E35: =VLOOKUP(B35, Расстояния!B:F, 5, 0) -> нет | H35: 46098.646 | I35: 46098.671 | J35: Котенко | L35: 1.1. | M35: =VLOOKUP(L35, Работы!A:B, 2, 0) -> Техническое обслуживание БС | N35: Техническое обслуживание БС | O35: 1 | P35: =IF(OR(L35="3.3.1.", L35="3.3.2.", L35="3.3.3.", L35="3.1.1.", L35="3.1.2.", L35="3.4.1.", L35="3.4.2."), 0, VLOOKUP(L35, Работы!$A$3:$D$184, 4, 0)) -> 4143 | T35: =IF(OR(L35="3.3.1.", L35="3.3.2.", L35="3.3.3."), VLOOKUP(L35, Работы!$A$3:$D$184, 4, 0), 0) -> 0 | U35: =IF(OR(L35="3.1.1."), VLOOKUP(L35, Работы!$A$3:$D$184, 4, 0), 0) -> 0 | V35: =IF(OR(L35="3.1.2."), VLOOKUP(L35, Работы!$A$3:$D$184, 4, 0), 0) -> 0 | Y35: =IF(OR(L35="3.2.1.", L35="3.2.2."), VLOOKUP(L35, Работы!$A$3:$D$184, 4, 0), 0) -> 0 | Z35: =IF(OR(L35="3.4.1.", L35="3.4.2."), VLOOKUP(L35, Работы!$A$3:$D$184, 4, 0), 0) -> 0 | AA35: =P35*O35+Q35*T35+R35*T35+S35*T35+U35+V35+W35*Y35+X35*Y35+Z35 -> 4143 | AE35: =AC35*AD35 -> 0 | AF35: =C35*Работы!$D$180 -> 3605.27 | AG35: =AA35+AE35+AF35+AL35+AM35 -> 7748.27 | AJ35: =AG35-AA35*AI35 -> 7748.27 | AL35: =IF(OR(E35="да"), 4040, 0) -> 0 | AM35: =IF(OR(D35="доп."), AA35*0.1, 0) -> 0
A36: =ROW(A36)-10 -> 26 | B36: RO0175 | C36: =VLOOKUP(B36, Расстояния!B:J, 9, 0) -> 70 | D36: =VLOOKUP(B36, Расстояния!B:K, 10, 0) -> осн. | E36: =VLOOKUP(B36, Расстояния!B:F, 5, 0) -> нет | F36: WO06723530 | G36: 46107.474 | H36: 46107.526 | I36: 46107.717 | J36: Голиков | L36: 3.1.1. | M36: =VLOOKUP(L36, Работы!A:B, 2, 0) -> Стоимость аварийно-восстановительных работ, заявка по которым получена в течение рабочего времени | N36: Замена 2-ух SFP, джампера | P36: =IF(OR(L36="3.3.1.", L36="3.3.2.", L36="3.3.3.", L36="3.1.1.", L36="3.1.2.", L36="3.4.1.", L36="3.4.2."), 0, VLOOKUP(L36, Работы!$A$3:$D$184, 4, 0)) -> 0 | T36: =IF(OR(L36="3.3.1.", L36="3.3.2.", L36="3.3.3."), VLOOKUP(L36, Работы!$A$3:$D$184, 4, 0), 0) -> 0 | U36: =IF(OR(L36="3.1.1."), VLOOKUP(L36, Работы!$A$3:$D$184, 4, 0), 0) -> 3956 | V36: =IF(OR(L36="3.1.2."), VLOOKUP(L36, Работы!$A$3:$D$184, 4, 0), 0) -> 0 | Y36: =IF(OR(L36="3.2.1.", L36="3.2.2."), VLOOKUP(L36, Работы!$A$3:$D$184, 4, 0), 0) -> 0 | Z36: =IF(OR(L36="3.4.1.", L36="3.4.2."), VLOOKUP(L36, Работы!$A$3:$D$184, 4, 0), 0) -> 0 | AA36: =P36*O36+Q36*T36+R36*T36+S36*T36+U36+V36+W36*Y36+X36*Y36+Z36 -> 3956 | AE36: =AC36*AD36 -> 0 | AF36: =C36*Работы!$D$180 -> 3766.7 | AG36: =AA36+AE36+AF36+AL36+AM36 -> 7722.7 | AJ36: =AG36-AA36*AI36 -> 7722.7 | AL36: =IF(OR(E36="да"), 4040, 0) -> 0 | AM36: =IF(OR(D36="доп."), AA36*0.1, 0) -> 0
A37: =ROW(A37)-10 -> 27 | B37: RO1075 | C37: =VLOOKUP(B37, Расстояния!B:J, 9, 0) -> 69 | D37: =VLOOKUP(B37, Расстояния!B:K, 10, 0) -> осн. | E37: =VLOOKUP(B37, Расстояния!B:F, 5, 0) -> нет | F37: WO06716427 | G37: 46100.369 | H37: 46100.407 | I37: 46100.549 | J37: Пастушенко | L37: 3.3.1. | M37: =VLOOKUP(L37, Работы!A:B, 2, 0) -> Стоимость Аварийно-восстановительных работ по обеспечению временного электроснабжения. (Ставка применяется с 1 часа выполнения Работ, для оплаты каждых не полных суток выполнения Работ) | N37: Генерация | P37: =IF(OR(L37="3.3.1.", L37="3.3.2.", L37="3.3.3.", L37="3.1.1.", L37="3.1.2.", L37="3.4.1.", L37="3.4.2."), 0, VLOOKUP(L37, Работы!$A$3:$D$184, 4, 0)) -> 0 | Q37: =ROUNDUP((I37-H37)*24, 0) -> 4 | T37: =IF(OR(L37="3.3.1.", L37="3.3.2.", L37="3.3.3."), VLOOKUP(L37, Работы!$A$3:$D$184, 4, 0), 0) -> 903 | U37: =IF(OR(L37="3.1.1."), VLOOKUP(L37, Работы!$A$3:$D$184, 4, 0), 0) -> 0 | V37: =IF(OR(L37="3.1.2."), VLOOKUP(L37, Работы!$A$3:$D$184, 4, 0), 0) -> 0 | Y37: =IF(OR(L37="3.2.1.", L37="3.2.2."), VLOOKUP(L37, Работы!$A$3:$D$184, 4, 0), 0) -> 0 | Z37: =IF(OR(L37="3.4.1.", L37="3.4.2."), VLOOKUP(L37, Работы!$A$3:$D$184, 4, 0), 0) -> 0 | AA37: =P37*O37+Q37*T37+R37*T37+S37*T37+U37+V37+W37*Y37+X37*Y37+Z37 -> 3612 | AE37: =AC37*AD37 -> 0 | AF37: =C37*Работы!$D$180 -> 3712.89 | AG37: =AA37+AE37+AF37+AL37+AM37 -> 7324.89 | AJ37: =AG37-AA37*AI37 -> 7324.89 | AL37: =IF(OR(E37="да"), 4040, 0) -> 0 | AM37: =IF(OR(D37="доп."), AA37*0.1, 0) -> 0
A38: =ROW(A38)-10 -> 28 | B38: RO0199 | C38: =VLOOKUP(B38, Расстояния!B:J, 9, 0) -> 63 | D38: =VLOOKUP(B38, Расстояния!B:K, 10, 0) -> осн. | E38: =VLOOKUP(B38, Расстояния!B:F, 5, 0) -> нет | F38: WO06714363 | G38: 46098.475 | H38: 46098.572 | I38: 46098.637 | J38: Юкин | L38: 3.1.1. | M38: =VLOOKUP(L38, Работы!A:B, 2, 0) -> Стоимость аварийно-восстановительных работ, заявка по которым получена в течение рабочего времени | N38: Сопровождение | P38: =IF(OR(L38="3.3.1.", L38="3.3.2.", L38="3.3.3.", L38="3.1.1.", L38="3.1.2.", L38="3.4.1.", L38="3.4.2."), 0, VLOOKUP(L38, Работы!$A$3:$D$184, 4, 0)) -> 0 | T38: =IF(OR(L38="3.3.1.", L38="3.3.2.", L38="3.3.3."), VLOOKUP(L38, Работы!$A$3:$D$184, 4, 0), 0) -> 0 | U38: =IF(OR(L38="3.1.1."), VLOOKUP(L38, Работы!$A$3:$D$184, 4, 0), 0) -> 3956 | V38: =IF(OR(L38="3.1.2."), VLOOKUP(L38, Работы!$A$3:$D$184, 4, 0), 0) -> 0 | Y38: =IF(OR(L38="3.2.1.", L38="3.2.2."), VLOOKUP(L38, Работы!$A$3:$D$184, 4, 0), 0) -> 0 | Z38: =IF(OR(L38="3.4.1.", L38="3.4.2."), VLOOKUP(L38, Работы!$A$3:$D$184, 4, 0), 0) -> 0 | AA38: =P38*O38+Q38*T38+R38*T38+S38*T38+U38+V38+W38*Y38+X38*Y38+Z38 -> 3956 | AE38: =AC38*AD38 -> 0 | AF38: =C38*Работы!$D$180 -> 3390.03 | AG38: =AA38+AE38+AF38+AL38+AM38 -> 7346.03 | AJ38: =AG38-AA38*AI38 -> 7346.03 | AL38: =IF(OR(E38="да"), 4040, 0) -> 0 | AM38: =IF(OR(D38="доп."), AA38*0.1, 0) -> 0
A39: =ROW(A39)-10 -> 29 | B39: RO0264 | C39: =VLOOKUP(B39, Расстояния!B:J, 9, 0) -> 64 | D39: =VLOOKUP(B39, Расстояния!B:K, 10, 0) -> осн. | E39: =VLOOKUP(B39, Расстояния!B:F, 5, 0) -> нет | F39: WO06726884 | G39: 46111.408 | H39: 46111.633 | I39: 46111.8 | J39: Голиков | L39: 2.2. | M39: =VLOOKUP(L39, Работы!A:B, 2, 0) -> Диагностика и замена модуля передатчиков БС на АМС, включая монтаж всех крепёжных элементов и кабелей, переключение джамперов и созданием логических объектов на стороне БС | N39: Чистка передатчика | O39: 1 | P39: =IF(OR(L39="3.3.1.", L39="3.3.2.", L39="3.3.3.", L39="3.1.1.", L39="3.1.2.", L39="3.4.1.", L39="3.4.2."), 0, VLOOKUP(L39, Работы!$A$3:$D$184, 4, 0)) -> 2830 | T39: =IF(OR(L39="3.3.1.", L39="3.3.2.", L39="3.3.3."), VLOOKUP(L39, Работы!$A$3:$D$184, 4, 0), 0) -> 0 | U39: =IF(OR(L39="3.1.1."), VLOOKUP(L39, Работы!$A$3:$D$184, 4, 0), 0) -> 0 | V39: =IF(OR(L39="3.1.2."), VLOOKUP(L39, Работы!$A$3:$D$184, 4, 0), 0) -> 0 | Y39: =IF(OR(L39="3.2.1.", L39="3.2.2."), VLOOKUP(L39, Работы!$A$3:$D$184, 4, 0), 0) -> 0 | Z39: =IF(OR(L39="3.4.1.", L39="3.4.2."), VLOOKUP(L39, Работы!$A$3:$D$184, 4, 0), 0) -> 0 | AA39: =P39*O39+Q39*T39+R39*T39+S39*T39+U39+V39+W39*Y39+X39*Y39+Z39 -> 2830 | AE39: =AC39*AD39 -> 0 | AF39: =C39*Работы!$D$180 -> 3443.84 | AG39: =AA39+AE39+AF39+AL39+AM39 -> 6273.84 | AJ39: =AG39-AA39*AI39 -> 6273.84 | AL39: =IF(OR(E39="да"), 4040, 0) -> 0 | AM39: =IF(OR(D39="доп."), AA39*0.1, 0) -> 0
A40: =ROW(A40)-10 -> 30 | B40: RO0270 | C40: =VLOOKUP(B40, Расстояния!B:J, 9, 0) -> 63 | D40: =VLOOKUP(B40, Расстояния!B:K, 10, 0) -> осн. | E40: =VLOOKUP(B40, Расстояния!B:F, 5, 0) -> нет | H40: 46101.562 | I40: 46101.646 | J40: Черкашин | L40: 1.1. | M40: =VLOOKUP(L40, Работы!A:B, 2, 0) -> Техническое обслуживание БС | N40: Техническое обслуживание БС | O40: 1 | P40: =IF(OR(L40="3.3.1.", L40="3.3.2.", L40="3.3.3.", L40="3.1.1.", L40="3.1.2.", L40="3.4.1.", L40="3.4.2."), 0, VLOOKUP(L40, Работы!$A$3:$D$184, 4, 0)) -> 4143 | T40: =IF(OR(L40="3.3.1.", L40="3.3.2.", L40="3.3.3."), VLOOKUP(L40, Работы!$A$3:$D$184, 4, 0), 0) -> 0 | U40: =IF(OR(L40="3.1.1."), VLOOKUP(L40, Работы!$A$3:$D$184, 4, 0), 0) -> 0 | V40: =IF(OR(L40="3.1.2."), VLOOKUP(L40, Работы!$A$3:$D$184, 4, 0), 0) -> 0 | Y40: =IF(OR(L40="3.2.1.", L40="3.2.2."), VLOOKUP(L40, Работы!$A$3:$D$184, 4, 0), 0) -> 0 | Z40: =IF(OR(L40="3.4.1.", L40="3.4.2."), VLOOKUP(L40, Работы!$A$3:$D$184, 4, 0), 0) -> 0 | AA40: =P40*O40+Q40*T40+R40*T40+S40*T40+U40+V40+W40*Y40+X40*Y40+Z40 -> 4143 | AE40: =AC40*AD40 -> 0 | AF40: =C40*Работы!$D$180 -> 3390.03 | AG40: =AA40+AE40+AF40+AL40+AM40 -> 7533.03 | AJ40: =AG40-AA40*AI40 -> 7533.03 | AL40: =IF(OR(E40="да"), 4040, 0) -> 0 | AM40: =IF(OR(D40="доп."), AA40*0.1, 0) -> 0
